## arugment label
```swift
func sayHello() {
    print("Hello")
}

let f1 = sayHello
//형식 추론 방식
f1()

func printHello(with name: String) {
    print("hello \(name)")
}
let f2: (String) -> () = printHello(with:)
//함수 표기

f2("World") // hello World
상수에 저장된 함수 호출시에 arugment label 사용 안한다.

func add(a: Int, b: Int) -> Int {
    return a + b
}

var f4: (Int, Int) -> Int = add(a:b:)
f4(1, 3)
```

### Error Handling
- Compile Time Error - 문법적 오류
- Run Time Error - 프로그램적 오류
문법적 오류에는 누락된 세미클론, 맞춤범이 틀린 변수 이름 등 잘못된 구문들이 있다.<br>
프로그램적 오류는 실행중인 프로그램에서 사용자의 입력, 잘못된 데이터 유형 또는 하드웨어 문제 등 다양한 문제들이 있다.<br>
존재하지 않는 파일 엑세스 시도, 메모리 부족 등이 있다.<br>

```swift
throw expression

// Throwing Function/ Method
func name(parameters) thorws -> ReturnType {
    statements
}
// Throwing Initializer
init(parameters) thorws {
    statements
}
//Throwing Closure
{ (parameters) throws -> ReturnType in
    statements
}
```

### do-catch
```swift
do {
    try expression
    statements
} catch pattern {
    statements
} catch pattern where condition {
    statements
}
```

```swift
enum CustomError: Error {
    case runtimeError(String)
}

func divideNumbers(_ a: Int, _ b: Int) throws -> Int {
    if b == 0 {
            throw CustomError.runtimeError("division by zero")
    }
    return a / b
}

do {
    let result = try divideNumbers(10, 0)
    print("The result is \(result)")
} catch CustomError.runtimeError(let errorMessage) {
    print("Runtime error: \(errorMessage)")
} catch {
    print("Unknown error: \(error)")
}
```
위에 코드에서는 divideNumbers 함수가 두개의 int값을 받아서 나눈 값을 반환한다.<br>
그러나 두 번째 인자가 0인 경우,<br>
CustomError 열거형의 .runtimeError case를 던지도록 구현되어 있다.<br>
CustomError 열거형의 .runtimeError case를 던지도록 구현되어 있다.<br>

do-catch 블록을 사용한다면 블록 내에서 오류를 처리할 수 있다.<br>
오류가 발생할 경우 catch 블록에서 처리한다.
